<?xml version="1.0"?>
<sdf version='1.7'>
  <world name='racecar_willow'>
    <light name='sun' type='directional'>
      <cast_shadows>1</cast_shadows>
      <pose>0 0 10 0 -0 0</pose>
      <diffuse>0.8 0.8 0.8 1</diffuse>
      <specular>0.2 0.2 0.2 1</specular>
      <attenuation>
        <range>1000</range>
        <constant>0.9</constant>
        <linear>0.01</linear>
        <quadratic>0.001</quadratic>
      </attenuation>
      <direction>-0.5 0.1 -0.9</direction>
      <spot>
        <inner_angle>0</inner_angle>
        <outer_angle>0</outer_angle>
        <falloff>0</falloff>
      </spot>
    </light>
    <model name='ground_plane'>
      <static>1</static>
      <link name='link'>
        <collision name='collision'>
          <geometry>
            <plane>
              <normal>0 0 1</normal>
              <size>150 150</size>
            </plane>
          </geometry>
          <surface>
            <friction>
              <ode>
                <mu>100</mu>
                <mu2>50</mu2>
              </ode>
              <torsional>
                <ode/>
              </torsional>
            </friction>
            <contact>
              <ode/>
            </contact>
            <bounce/>
          </surface>
          <max_contacts>10</max_contacts>
        </collision>
        <visual name='visual'>
          <cast_shadows>0</cast_shadows>
          <geometry>
            <plane>
              <normal>0 0 1</normal>
              <size>150 150</size>
            </plane>
          </geometry>
          <material>
            <script>
              <uri>file://media/materials/scripts/gazebo.material</uri>
              <name>Gazebo/Grey</name>
            </script>
          </material>
        </visual>
        <self_collide>0</self_collide>
        <enable_wind>0</enable_wind>
        <kinematic>0</kinematic>
      </link>
    </model>
    <gravity>0 0 -9.8</gravity>
    <magnetic_field>6e-06 2.3e-05 -4.2e-05</magnetic_field>
    <atmosphere type='adiabatic'/>
    <physics type='ode'>
      <max_step_size>0.001</max_step_size>
      <real_time_factor>1</real_time_factor>
      <real_time_update_rate>1000</real_time_update_rate>
    </physics>
    <scene>
      <ambient>0.4 0.4 0.4 1</ambient>
      <background>0.7 0.7 0.7 1</background>
      <shadows>1</shadows>
    </scene>
    <wind/>
    <spherical_coordinates>
      <surface_model>EARTH_WGS84</surface_model>
      <latitude_deg>0</latitude_deg>
      <longitude_deg>0</longitude_deg>
      <elevation>0</elevation>
      <heading_deg>0</heading_deg>
    </spherical_coordinates>
    <model name='racecar1'>
      <link name='base_link'>
        <inertial>
          <pose>0.151394 0 0.052361 0 -0 0</pose>
          <mass>4.13003</mass>
          <inertia>
            <ixx>0.0113243</ixx>
            <ixy>0</ixy>
            <ixz>-0.00110794</ixz>
            <iyy>0.0528584</iyy>
            <iyz>0</iyz>
            <izz>0.0603912</izz>
          </inertia>
        </inertial>
        <collision name='base_link_fixed_joint_lump__laser_collision'>
          <pose>0.265 0 0.125 0 -0 0</pose>
          <geometry>
            <box>
              <size>0.1 0.1 0.1</size>
            </box>
          </geometry>
          <surface>
            <contact>
              <ode/>
            </contact>
            <friction>
              <ode/>
              <torsional>
                <ode/>
              </torsional>
            </friction>
            <bounce/>
          </surface>
          <max_contacts>10</max_contacts>
        </collision>
        <collision name='base_link_fixed_joint_lump__zed_camera_link_collision_1'>
          <pose>0.39 0 0.09 0 -0 0</pose>
          <geometry>
            <box>
              <size>0.033 0.175 0.03</size>
            </box>
          </geometry>
          <surface>
            <contact>
              <ode/>
            </contact>
            <bounce/>
            <friction>
              <torsional>
                <ode/>
              </torsional>
              <ode/>
            </friction>
          </surface>
          <max_contacts>10</max_contacts>
        </collision>
        <visual name='base_link_fixed_joint_lump__chassis_visual'>
          <pose>0 0 0.05 0 -0 0</pose>
          <geometry>
            <mesh>
              <scale>1 1 1</scale>
              <uri>/home/dschori/catkin_ws/src/racecar-simulator/racecar_description/meshes/chassis.STL</uri>
            </mesh>
          </geometry>
          <material>
            <script>
              <name>Gazebo/Blue</name>
              <uri>file://media/materials/scripts/gazebo.material</uri>
            </script>
          </material>
        </visual>
        <visual name='base_link_fixed_joint_lump__laser_visual_1'>
          <pose>0.265 0 0.125 0 -0 0</pose>
          <geometry>
            <mesh>
              <scale>1 1 1</scale>
              <uri>/home/dschori/catkin_ws/src/racecar-simulator/racecar_description/meshes/hokuyo.dae</uri>
            </mesh>
          </geometry>
          <material>
            <script>
              <name>Gazebo/Grey</name>
              <uri>file://media/materials/scripts/gazebo.material</uri>
            </script>
          </material>
        </visual>
        <visual name='base_link_fixed_joint_lump__zed_camera_link_visual_2'>
          <pose>0.39 0 0.09 0 -0 0</pose>
          <geometry>
            <box>
              <size>0.033 0.175 0.03</size>
            </box>
          </geometry>
        </visual>
        <velocity_decay/>
        <velocity_decay/>
        <sensor name='hokuyo_sensor' type='ray'>
          <visualize>1</visualize>
          <update_rate>40</update_rate>
          <ray>
            <scan>
              <horizontal>
                <samples>1081</samples>
                <resolution>1</resolution>
                <min_angle>-2.35619</min_angle>
                <max_angle>2.35619</max_angle>
              </horizontal>
              <vertical>
                <samples>1</samples>
                <min_angle>0</min_angle>
                <max_angle>0</max_angle>
              </vertical>
            </scan>
            <range>
              <min>0.1</min>
              <max>10</max>
              <resolution>0.01</resolution>
            </range>
            <noise>
              <mean>0</mean>
              <stddev>0.01</stddev>
              <type>gaussian</type>
            </noise>
          </ray>
          <plugin name='gazebo_ros_hokuyo_controller' filename='libgazebo_ros_laser.so'>
            <topicName>/scan</topicName>
            <frameName>laser</frameName>
            <robotNamespace>/</robotNamespace>
          </plugin>
          <pose>0.265 0 0.125 0 -0 0</pose>
        </sensor>
        <gravity>1</gravity>
        <velocity_decay/>
        <sensor name='zed_camera_left_sensor' type='camera'>
          <update_rate>30</update_rate>
          <camera name='zed_camera_left_camera'>
            <horizontal_fov>0.870922</horizontal_fov>
            <image>
              <width>640</width>
              <height>480</height>
              <format>B8G8R8</format>
            </image>
            <clip>
              <near>0.02</near>
              <far>300</far>
            </clip>
            <noise>
              <type>gaussian</type>
              <mean>0</mean>
              <stddev>0.007</stddev>
            </noise>
          </camera>
          <plugin name='camera_controller' filename='libgazebo_ros_camera.so'>
            <alwaysOn>1</alwaysOn>
            <updateRate>30.0</updateRate>
            <cameraName>/camera/zed</cameraName>
            <imageTopicName>rgb/image_rect_color</imageTopicName>
            <cameraInfoTopicName>rgb/camera_info</cameraInfoTopicName>
            <frameName>camera_link</frameName>
            <hackBaseline>0</hackBaseline>
            <distortionK1>0.0</distortionK1>
            <distortionK2>0.0</distortionK2>
            <distortionK3>0.0</distortionK3>
            <distortionT1>0.0</distortionT1>
            <distortionT2>0.0</distortionT2>
            <robotNamespace>/</robotNamespace>
          </plugin>
          <pose>0.39 0.06 0.09 0 -0 0</pose>
        </sensor>
        <self_collide>0</self_collide>
        <enable_wind>0</enable_wind>
        <kinematic>0</kinematic>
      </link>
      <joint name='left_rear_wheel_joint' type='revolute'>
        <pose relative_to='base_link'>0 0.1 0.05 1.5708 -0 0</pose>
        <parent>base_link</parent>
        <child>left_rear_wheel</child>
        <axis>
          <xyz>0 0 -1</xyz>
          <limit>
            <lower>-1e+16</lower>
            <upper>1e+16</upper>
          </limit>
          <dynamics>
            <spring_reference>0</spring_reference>
            <spring_stiffness>0</spring_stiffness>
          </dynamics>
        </axis>
      </joint>
      <link name='left_rear_wheel'>
        <pose relative_to='left_rear_wheel_joint'>0 0 0 0 -0 0</pose>
        <inertial>
          <pose>0 0 -0.0225 0 -0 0</pose>
          <mass>0.34055</mass>
          <inertia>
            <ixx>0.00026046</ixx>
            <ixy>0</ixy>
            <ixz>0</ixz>
            <iyy>0.00026046</iyy>
            <iyz>0</iyz>
            <izz>0.00041226</izz>
          </inertia>
        </inertial>
        <collision name='left_rear_wheel_collision'>
          <pose>0 0 -0.0225 0 -0 0</pose>
          <geometry>
            <cylinder>
              <length>0.045</length>
              <radius>0.05</radius>
            </cylinder>
          </geometry>
          <surface>
            <contact>
              <ode>
                <kp>1e+07</kp>
                <kd>1</kd>
              </ode>
            </contact>
            <friction>
              <ode>
                <mu>1</mu>
                <mu2>1</mu2>
                <fdir1>1 0 0</fdir1>
              </ode>
              <torsional>
                <ode/>
              </torsional>
            </friction>
            <bounce/>
          </surface>
          <max_contacts>10</max_contacts>
        </collision>
        <visual name='left_rear_wheel_visual'>
          <pose>0 0 0 0 -0 0</pose>
          <geometry>
            <mesh>
              <scale>1 1 1</scale>
              <uri>/home/dschori/catkin_ws/src/racecar-simulator/racecar_description/meshes/left_rear_wheel.STL</uri>
            </mesh>
          </geometry>
          <material>
            <script>
              <name>Gazebo/Black</name>
              <uri>file://media/materials/scripts/gazebo.material</uri>
            </script>
          </material>
        </visual>
        <gravity>1</gravity>
        <velocity_decay/>
        <self_collide>0</self_collide>
        <enable_wind>0</enable_wind>
        <kinematic>0</kinematic>
      </link>
      <joint name='left_steering_hinge_joint' type='revolute'>
        <pose relative_to='base_link'>0.325 0.1 0.05 3.14159 1.57079 3.14159</pose>
        <parent>base_link</parent>
        <child>left_steering_hinge</child>
        <axis>
          <xyz>-1 0 0</xyz>
          <limit>
            <lower>-1</lower>
            <upper>1</upper>
            <effort>10</effort>
            <velocity>100</velocity>
          </limit>
          <dynamics>
            <spring_reference>0</spring_reference>
            <spring_stiffness>0</spring_stiffness>
          </dynamics>
        </axis>
      </joint>
      <link name='left_steering_hinge'>
        <pose relative_to='left_steering_hinge_joint'>0 0 0 0 -0 0</pose>
        <inertial>
          <pose>0 0 0 0 -0 0</pose>
          <mass>0.1</mass>
          <inertia>
            <ixx>4e-06</ixx>
            <ixy>0</ixy>
            <ixz>0</ixz>
            <iyy>4e-06</iyy>
            <iyz>0</iyz>
            <izz>4e-06</izz>
          </inertia>
        </inertial>
        <visual name='left_steering_hinge_visual'>
          <pose>0 0 0 0 -0 0</pose>
          <geometry>
            <mesh>
              <scale>1 1 1</scale>
              <uri>/home/dschori/catkin_ws/src/racecar-simulator/racecar_description/meshes/left_steering_hinge.STL</uri>
            </mesh>
          </geometry>
        </visual>
        <self_collide>0</self_collide>
        <enable_wind>0</enable_wind>
        <kinematic>0</kinematic>
      </link>
      <joint name='left_front_wheel_joint' type='revolute'>
        <pose relative_to='left_steering_hinge'>0 0 0 1.5708 -0 0</pose>
        <parent>left_steering_hinge</parent>
        <child>left_front_wheel</child>
        <axis>
          <xyz>0 0 -1</xyz>
          <limit>
            <lower>-1e+16</lower>
            <upper>1e+16</upper>
          </limit>
          <dynamics>
            <spring_reference>0</spring_reference>
            <spring_stiffness>0</spring_stiffness>
          </dynamics>
        </axis>
      </joint>
      <link name='left_front_wheel'>
        <pose relative_to='left_front_wheel_joint'>0 0 0 0 -0 0</pose>
        <inertial>
          <pose>0 0 -0.0225 0 -0 0</pose>
          <mass>0.34055</mass>
          <inertia>
            <ixx>0.00026046</ixx>
            <ixy>0</ixy>
            <ixz>0</ixz>
            <iyy>0.00026046</iyy>
            <iyz>0</iyz>
            <izz>0.00041226</izz>
          </inertia>
        </inertial>
        <collision name='left_front_wheel_collision'>
          <pose>0 0 -0.0225 0 -0 0</pose>
          <geometry>
            <cylinder>
              <length>0.045</length>
              <radius>0.05</radius>
            </cylinder>
          </geometry>
          <surface>
            <contact>
              <ode>
                <kp>1e+07</kp>
                <kd>1</kd>
              </ode>
            </contact>
            <friction>
              <ode>
                <mu>1</mu>
                <mu2>1</mu2>
                <fdir1>0 0 1</fdir1>
              </ode>
              <torsional>
                <ode/>
              </torsional>
            </friction>
            <bounce/>
          </surface>
          <max_contacts>10</max_contacts>
        </collision>
        <visual name='left_front_wheel_visual'>
          <pose>0 0 0 0 -0 0</pose>
          <geometry>
            <mesh>
              <scale>1 1 1</scale>
              <uri>/home/dschori/catkin_ws/src/racecar-simulator/racecar_description/meshes/left_front_wheel.STL</uri>
            </mesh>
          </geometry>
          <material>
            <script>
              <name>Gazebo/Black</name>
              <uri>file://media/materials/scripts/gazebo.material</uri>
            </script>
          </material>
        </visual>
        <gravity>1</gravity>
        <velocity_decay/>
        <self_collide>0</self_collide>
        <enable_wind>0</enable_wind>
        <kinematic>0</kinematic>
      </link>
      <joint name='right_rear_wheel_joint' type='revolute'>
        <pose relative_to='base_link'>0 -0.1 0.05 1.5708 -0 0</pose>
        <parent>base_link</parent>
        <child>right_rear_wheel</child>
        <axis>
          <xyz>0 0 -1</xyz>
          <limit>
            <lower>-1e+16</lower>
            <upper>1e+16</upper>
          </limit>
          <dynamics>
            <spring_reference>0</spring_reference>
            <spring_stiffness>0</spring_stiffness>
          </dynamics>
        </axis>
      </joint>
      <link name='right_rear_wheel'>
        <pose relative_to='right_rear_wheel_joint'>0 0 0 0 -0 0</pose>
        <inertial>
          <pose>0 0 0.0225 0 -0 0</pose>
          <mass>0.34055</mass>
          <inertia>
            <ixx>0.00026046</ixx>
            <ixy>0</ixy>
            <ixz>0</ixz>
            <iyy>0.00026046</iyy>
            <iyz>0</iyz>
            <izz>0.00041226</izz>
          </inertia>
        </inertial>
        <collision name='right_rear_wheel_collision'>
          <pose>0 0 0.0225 0 -0 0</pose>
          <geometry>
            <cylinder>
              <length>0.045</length>
              <radius>0.05</radius>
            </cylinder>
          </geometry>
          <surface>
            <contact>
              <ode>
                <kp>1e+07</kp>
                <kd>1</kd>
              </ode>
            </contact>
            <friction>
              <ode>
                <mu>1</mu>
                <mu2>1</mu2>
                <fdir1>1 0 0</fdir1>
              </ode>
              <torsional>
                <ode/>
              </torsional>
            </friction>
            <bounce/>
          </surface>
          <max_contacts>10</max_contacts>
        </collision>
        <visual name='right_rear_wheel_visual'>
          <pose>0 0 0 0 -0 0</pose>
          <geometry>
            <mesh>
              <scale>1 1 1</scale>
              <uri>/home/dschori/catkin_ws/src/racecar-simulator/racecar_description/meshes/right_rear_wheel.STL</uri>
            </mesh>
          </geometry>
          <material>
            <script>
              <name>Gazebo/Black</name>
              <uri>file://media/materials/scripts/gazebo.material</uri>
            </script>
          </material>
        </visual>
        <gravity>1</gravity>
        <velocity_decay/>
        <self_collide>0</self_collide>
        <enable_wind>0</enable_wind>
        <kinematic>0</kinematic>
      </link>
      <joint name='right_steering_hinge_joint' type='revolute'>
        <pose relative_to='base_link'>0.325 -0.1 0.05 3.14159 1.57079 3.14159</pose>
        <parent>base_link</parent>
        <child>right_steering_hinge</child>
        <axis>
          <xyz>-1 0 0</xyz>
          <limit>
            <lower>-1e+16</lower>
            <upper>1e+16</upper>
          </limit>
          <dynamics>
            <spring_reference>0</spring_reference>
            <spring_stiffness>0</spring_stiffness>
          </dynamics>
        </axis>
      </joint>
      <link name='right_steering_hinge'>
        <pose relative_to='right_steering_hinge_joint'>0 0 0 0 -0 0</pose>
        <inertial>
          <pose>0 0 0 0 -0 0</pose>
          <mass>0.1</mass>
          <inertia>
            <ixx>4e-06</ixx>
            <ixy>0</ixy>
            <ixz>0</ixz>
            <iyy>4e-06</iyy>
            <iyz>0</iyz>
            <izz>4e-06</izz>
          </inertia>
        </inertial>
        <visual name='right_steering_hinge_visual'>
          <pose>0 0 0 0 -0 0</pose>
          <geometry>
            <mesh>
              <scale>1 1 1</scale>
              <uri>/home/dschori/catkin_ws/src/racecar-simulator/racecar_description/meshes/right_steering_hinge.STL</uri>
            </mesh>
          </geometry>
        </visual>
        <self_collide>0</self_collide>
        <enable_wind>0</enable_wind>
        <kinematic>0</kinematic>
      </link>
      <joint name='right_front_wheel_joint' type='revolute'>
        <pose relative_to='right_steering_hinge'>0 0 0 1.5708 -0 0</pose>
        <parent>right_steering_hinge</parent>
        <child>right_front_wheel</child>
        <axis>
          <xyz>0 0 -1</xyz>
          <limit>
            <lower>-1e+16</lower>
            <upper>1e+16</upper>
          </limit>
          <dynamics>
            <spring_reference>0</spring_reference>
            <spring_stiffness>0</spring_stiffness>
          </dynamics>
        </axis>
      </joint>
      <link name='right_front_wheel'>
        <pose relative_to='right_front_wheel_joint'>0 0 0 0 -0 0</pose>
        <inertial>
          <pose>0 0 0.0225 0 -0 0</pose>
          <mass>0.34055</mass>
          <inertia>
            <ixx>0.00026046</ixx>
            <ixy>0</ixy>
            <ixz>0</ixz>
            <iyy>0.00026046</iyy>
            <iyz>0</iyz>
            <izz>0.00041226</izz>
          </inertia>
        </inertial>
        <collision name='right_front_wheel_collision'>
          <pose>0 0 0.0225 0 -0 0</pose>
          <geometry>
            <cylinder>
              <length>0.045</length>
              <radius>0.05</radius>
            </cylinder>
          </geometry>
          <surface>
            <contact>
              <ode>
                <kp>1e+07</kp>
                <kd>1</kd>
              </ode>
            </contact>
            <friction>
              <ode>
                <mu>1</mu>
                <mu2>1</mu2>
                <fdir1>0 0 1</fdir1>
              </ode>
              <torsional>
                <ode/>
              </torsional>
            </friction>
            <bounce/>
          </surface>
          <max_contacts>10</max_contacts>
        </collision>
        <visual name='right_front_wheel_visual'>
          <pose>0 0 0 0 -0 0</pose>
          <geometry>
            <mesh>
              <scale>1 1 1</scale>
              <uri>/home/dschori/catkin_ws/src/racecar-simulator/racecar_description/meshes/right_front_wheel.STL</uri>
            </mesh>
          </geometry>
          <material>
            <script>
              <name>Gazebo/Black</name>
              <uri>file://media/materials/scripts/gazebo.material</uri>
            </script>
          </material>
        </visual>
        <gravity>1</gravity>
        <velocity_decay/>
        <self_collide>0</self_collide>
        <enable_wind>0</enable_wind>
        <kinematic>0</kinematic>
      </link>
      <static>0</static>
      <plugin name='gazebo_ros_control' filename='libgazebo_ros_control.so'>
        <robotNamespace>/racecar</robotNamespace>
        <robotSimType>gazebo_ros_control/DefaultRobotHWSim</robotSimType>
      </plugin>
      <pose>0 0 0.05 0 -0 0</pose>
    </model>
    <model name='willowgarage'>
      <static>1</static>
      <pose>-15.4411 -29.0113 0 0 -0 0</pose>
      <link name='walls'>
        <collision name='collision'>
          <geometry>
            <mesh>
              <uri>model://willowgarage/meshes/willowgarage_collision.dae</uri>
            </mesh>
          </geometry>
          <surface>
            <contact>
              <ode/>
            </contact>
            <bounce/>
            <friction>
              <torsional>
                <ode/>
              </torsional>
              <ode/>
            </friction>
          </surface>
          <max_contacts>10</max_contacts>
        </collision>
        <visual name='visual'>
          <geometry>
            <mesh>
              <uri>model://willowgarage/meshes/willowgarage_visual.dae</uri>
            </mesh>
          </geometry>
          <cast_shadows>0</cast_shadows>
        </visual>
        <self_collide>0</self_collide>
        <enable_wind>0</enable_wind>
        <kinematic>0</kinematic>
      </link>
    </model>
    <state world_name='racecar_willow'>
      <sim_time>320 667000000</sim_time>
      <real_time>186 42608262</real_time>
      <wall_time>1609529801 393383275</wall_time>
      <iterations>178360</iterations>
      <model name='ground_plane'>
        <pose>0 0 0 0 -0 0</pose>
        <scale>1 1 1</scale>
        <link name='link'>
          <pose>0 0 0 0 -0 0</pose>
          <velocity>0 0 0 0 -0 0</velocity>
          <acceleration>0 0 0 0 -0 0</acceleration>
          <wrench>0 0 0 0 -0 0</wrench>
        </link>
      </model>
      <model name='racecar2'>
        <pose>-9.4e-05 -1e-06 -1e-06 -0 2e-06 -7e-06</pose>
        <scale>1 1 1</scale>
        <link name='base_link'>
          <pose>-9.4e-05 -1e-06 -1e-06 -0 2e-06 -7e-06</pose>
          <velocity>0 -0 7e-06 1e-06 -6e-06 0</velocity>
          <acceleration>0 0 0 -0 -0 -0</acceleration>
          <wrench>0 0 0 0 -0 0</wrench>
        </link>
        <link name='left_front_wheel'>
          <pose>0.324907 0.099997 0.049999 1.58575 1.56913 0.014683</pose>
          <velocity>-0 2e-06 7e-06 -4.9e-05 -5e-06 0</velocity>
          <acceleration>0 0 -0 0 -0.000557 0</acceleration>
          <wrench>0 0 -0 0 -0 0</wrench>
        </link>
        <link name='left_rear_wheel'>
          <pose>-9.3e-05 0.099999 0.049999 1.57079 -0.001866 -7e-06</pose>
          <velocity>-0 -0 7e-06 4e-06 -6e-06 0</velocity>
          <acceleration>0 0 0 0 -0.000359 0</acceleration>
          <wrench>0 0 0 0 -0 0</wrench>
        </link>
        <link name='left_steering_hinge'>
          <pose>0.324907 0.099997 0.049999 1.81358 1.57076 1.81331</pose>
          <velocity>-0 2e-06 9e-06 -0.000134 -6e-06 1e-06</velocity>
          <acceleration>0 0 0 0 -0 0</acceleration>
          <wrench>0 0 0 0 -0 0</wrench>
        </link>
        <link name='right_front_wheel'>
          <pose>0.324905 -0.100003 0.049999 1.55819 1.56886 -0.012799</pose>
          <velocity>-0 -3e-06 8e-06 6.1e-05 -4e-06 0</velocity>
          <acceleration>0 0 -0 0 -0.00115 0</acceleration>
          <wrench>0 0 -0 0 -0 0</wrench>
        </link>
        <link name='right_rear_wheel'>
          <pose>-9.5e-05 -0.100001 0.049999 1.5708 -0.001906 -7e-06</pose>
          <velocity>-0 -0 7e-06 2e-06 -6e-06 0</velocity>
          <acceleration>0 -0 -0 0 -0.000167 0</acceleration>
          <wrench>0 -0 -0 0 -0 0</wrench>
        </link>
        <link name='right_steering_hinge'>
          <pose>0.324905 -0.100003 0.049999 2.20805 1.57078 2.20786</pose>
          <velocity>-0 0 9e-06 -4.2e-05 -6e-06 1e-06</velocity>
          <acceleration>0 0 -0 0 -0 0</acceleration>
          <wrench>0 0 -0 0 -0 0</wrench>
        </link>
      </model>
      <model name='unit_box'>
        <pose>1.93659 14.8108 0.5 0 0 -0.149036</pose>
        <scale>1 1 1</scale>
        <link name='link'>
          <pose>1.93659 14.8108 0.5 0 0 -0.149036</pose>
          <velocity>0 0 0 0 -0 0</velocity>
          <acceleration>-9.67463 1.45831 9.78363 -2.91659 -0.499698 -3.8e-05</acceleration>
          <wrench>-9.67463 1.45831 9.78363 0 -0 0</wrench>
        </link>
      </model>
      <model name='unit_box_0'>
        <pose>0.881517 14.2051 0.5 2e-06 2e-06 0.131016</pose>
        <scale>1 1 1</scale>
        <link name='link'>
          <pose>0.881517 14.2051 0.5 2e-06 2e-06 0.131016</pose>
          <velocity>0 0 0 0 -0 0</velocity>
          <acceleration>-1.01223 -1.31948 -1.62378 -0.502634 -1.11714 -3.14159</acceleration>
          <wrench>-1.01223 -1.31948 -1.62378 0 -0 0</wrench>
        </link>
      </model>
      <model name='unit_box_1'>
        <pose>-4.60316 -29.049 0.499995 0 1e-05 0</pose>
        <scale>1 1 1</scale>
        <link name='link'>
          <pose>-4.60316 -29.049 0.499995 0 1e-05 0</pose>
          <velocity>0 0 0 0 -0 0</velocity>
          <acceleration>0.010615 -0.006191 -9.78231 0.012424 0.021225 1.8e-05</acceleration>
          <wrench>0.010615 -0.006191 -9.78231 0 -0 0</wrench>
        </link>
      </model>
      <model name='unit_box_2'>
        <pose>33.9923 -24.345 0.499995 0 1e-05 0.085664</pose>
        <scale>1 1 1</scale>
        <link name='link'>
          <pose>33.9923 -24.345 0.499995 0 1e-05 0.085664</pose>
          <velocity>0 0 0 0 -0 0</velocity>
          <acceleration>0.0097 0.005796 -9.78307 -0.011588 0.019405 1e-06</acceleration>
          <wrench>0.0097 0.005796 -9.78307 0 -0 0</wrench>
        </link>
      </model>
      <model name='unit_box_3'>
        <pose>33.8343 -0.75653 0.5 0 -0 0</pose>
        <scale>1 1 1</scale>
        <link name='link'>
          <pose>33.8343 -0.75653 0.5 0 -0 0</pose>
          <velocity>0 0 0 0 -0 0</velocity>
          <acceleration>-0.004709 -9.78112 9.78158 0.712677 -0.009414 -4.3e-05</acceleration>
          <wrench>-0.004709 -9.78112 9.78158 0 -0 0</wrench>
        </link>
      </model>
      <model name='willowgarage'>
        <pose>-15.4411 -29.0113 0 0 -0 0</pose>
        <scale>1 1 1</scale>
        <link name='walls'>
          <pose>-15.4411 -29.0113 0 0 -0 0</pose>
          <velocity>0 0 0 0 -0 0</velocity>
          <acceleration>0 0 0 0 -0 0</acceleration>
          <wrench>0 0 0 0 -0 0</wrench>
        </link>
      </model>
      <light name='sun'>
        <pose>0 0 10 0 -0 0</pose>
      </light>
    </state>
    <gui fullscreen='0'>
      <camera name='user_camera'>
        <pose>47.6596 -37.3672 70.61 0 0.977797 2.02019</pose>
        <view_controller>orbit</view_controller>
        <projection_type>perspective</projection_type>
      </camera>
    </gui>
    <model name='unit_box'>
      <pose>1.74483 14.3619 0.5 0 -0 0</pose>
      <link name='link'>
        <inertial>
          <mass>1</mass>
          <inertia>
            <ixx>0.166667</ixx>
            <ixy>0</ixy>
            <ixz>0</ixz>
            <iyy>0.166667</iyy>
            <iyz>0</iyz>
            <izz>0.166667</izz>
          </inertia>
          <pose>0 0 0 0 -0 0</pose>
        </inertial>
        <collision name='collision'>
          <geometry>
            <box>
              <size>1 1 1</size>
            </box>
          </geometry>
          <surface>
            <contact>
              <ode/>
            </contact>
            <bounce/>
            <friction>
              <torsional>
                <ode/>
              </torsional>
              <ode/>
            </friction>
          </surface>
          <max_contacts>10</max_contacts>
        </collision>
        <visual name='visual'>
          <geometry>
            <box>
              <size>1 1 1</size>
            </box>
          </geometry>
          <material>
            <script>
              <name>Gazebo/Grey</name>
              <uri>file://media/materials/scripts/gazebo.material</uri>
            </script>
          </material>
        </visual>
        <self_collide>0</self_collide>
        <enable_wind>0</enable_wind>
        <kinematic>0</kinematic>
      </link>
    </model>
    <model name='unit_box_0'>
      <pose>0.782301 14.3744 0.5 0 -0 0</pose>
      <link name='link'>
        <inertial>
          <mass>1</mass>
          <inertia>
            <ixx>0.166667</ixx>
            <ixy>0</ixy>
            <ixz>0</ixz>
            <iyy>0.166667</iyy>
            <iyz>0</iyz>
            <izz>0.166667</izz>
          </inertia>
          <pose>0 0 0 0 -0 0</pose>
        </inertial>
        <collision name='collision'>
          <geometry>
            <box>
              <size>1 1 1</size>
            </box>
          </geometry>
          <surface>
            <contact>
              <ode/>
            </contact>
            <bounce/>
            <friction>
              <torsional>
                <ode/>
              </torsional>
              <ode/>
            </friction>
          </surface>
          <max_contacts>10</max_contacts>
        </collision>
        <visual name='visual'>
          <geometry>
            <box>
              <size>1 1 1</size>
            </box>
          </geometry>
          <material>
            <script>
              <name>Gazebo/Grey</name>
              <uri>file://media/materials/scripts/gazebo.material</uri>
            </script>
          </material>
        </visual>
        <self_collide>0</self_collide>
        <enable_wind>0</enable_wind>
        <kinematic>0</kinematic>
      </link>
    </model>
    <model name='unit_box_1'>
      <pose>-4.60317 -29.049 0.5 0 -0 0</pose>
      <link name='link'>
        <inertial>
          <mass>1</mass>
          <inertia>
            <ixx>0.166667</ixx>
            <ixy>0</ixy>
            <ixz>0</ixz>
            <iyy>0.166667</iyy>
            <iyz>0</iyz>
            <izz>0.166667</izz>
          </inertia>
          <pose>0 0 0 0 -0 0</pose>
        </inertial>
        <collision name='collision'>
          <geometry>
            <box>
              <size>1 1 1</size>
            </box>
          </geometry>
          <surface>
            <contact>
              <ode/>
            </contact>
            <bounce/>
            <friction>
              <torsional>
                <ode/>
              </torsional>
              <ode/>
            </friction>
          </surface>
          <max_contacts>10</max_contacts>
        </collision>
        <visual name='visual'>
          <geometry>
            <box>
              <size>1 1 1</size>
            </box>
          </geometry>
          <material>
            <script>
              <name>Gazebo/Grey</name>
              <uri>file://media/materials/scripts/gazebo.material</uri>
            </script>
          </material>
        </visual>
        <self_collide>0</self_collide>
        <enable_wind>0</enable_wind>
        <kinematic>0</kinematic>
      </link>
    </model>
    <model name='unit_box_2'>
      <pose>33.893 -24.3773 0.5 0 -0 0</pose>
      <link name='link'>
        <inertial>
          <mass>1</mass>
          <inertia>
            <ixx>0.166667</ixx>
            <ixy>0</ixy>
            <ixz>0</ixz>
            <iyy>0.166667</iyy>
            <iyz>0</iyz>
            <izz>0.166667</izz>
          </inertia>
          <pose>0 0 0 0 -0 0</pose>
        </inertial>
        <collision name='collision'>
          <geometry>
            <box>
              <size>1 1 1</size>
            </box>
          </geometry>
          <surface>
            <contact>
              <ode/>
            </contact>
            <bounce/>
            <friction>
              <torsional>
                <ode/>
              </torsional>
              <ode/>
            </friction>
          </surface>
          <max_contacts>10</max_contacts>
        </collision>
        <visual name='visual'>
          <geometry>
            <box>
              <size>1 1 1</size>
            </box>
          </geometry>
          <material>
            <script>
              <name>Gazebo/Grey</name>
              <uri>file://media/materials/scripts/gazebo.material</uri>
            </script>
          </material>
        </visual>
        <self_collide>0</self_collide>
        <enable_wind>0</enable_wind>
        <kinematic>0</kinematic>
      </link>
    </model>
    <model name='unit_box_3'>
      <pose>33.8343 -0.75653 0.5 0 -0 0</pose>
      <link name='link'>
        <inertial>
          <mass>1</mass>
          <inertia>
            <ixx>0.166667</ixx>
            <ixy>0</ixy>
            <ixz>0</ixz>
            <iyy>0.166667</iyy>
            <iyz>0</iyz>
            <izz>0.166667</izz>
          </inertia>
          <pose>0 0 0 0 -0 0</pose>
        </inertial>
        <collision name='collision'>
          <geometry>
            <box>
              <size>1 1 1</size>
            </box>
          </geometry>
          <surface>
            <contact>
              <ode/>
            </contact>
            <bounce/>
            <friction>
              <torsional>
                <ode/>
              </torsional>
              <ode/>
            </friction>
          </surface>
          <max_contacts>10</max_contacts>
        </collision>
        <visual name='visual'>
          <geometry>
            <box>
              <size>1 1 1</size>
            </box>
          </geometry>
          <material>
            <script>
              <name>Gazebo/Grey</name>
              <uri>file://media/materials/scripts/gazebo.material</uri>
            </script>
          </material>
        </visual>
        <self_collide>0</self_collide>
        <enable_wind>0</enable_wind>
        <kinematic>0</kinematic>
      </link>
    </model>
  </world>
</sdf>
